Workbook

Sheet Cover
C16: Plan Personal Reducción Huella de Carbono | J16: © AHdC - 2022,2023,2024, 2025+
C28: Equipo de I+D | F28: V4.1 | G28: 45589 | I28: Updated by: Maria Luz Sanz Villarroya
F29: V4.2 | G29: 44204 | I29: Updated by: Revisores del Campus Huella de Carbono
C31: Para cualquier información diriíjase a Secretaria@asociacionhuelladecarbono.org

Sheet Guia
A1: Cómo Utilizar Este Excel
A3: El objetivo de esta hoja de calculo, es proporcionar una herramienta interactiva para evaluar y reducir la huella de carbono. Incluye una lista de medidas concretas para reducir la huella de carbono y una orientación para calcular la reducción asociada a cada medida
A4: Cada usuario podrá revisar estas opciones y seleccionar las medidas que puede implementar, el grado en el que puede llevarlas a cabo, su coste previsible y la cantidad de emisiones que puede eliminar con cada acción, creando su propio Plan de reducción.
A5: Este Excel se compone de varias medidas que podemos adoptar en nuestra vida personal para reducir la huella de carbono.
A7: Estas medidas que tratan de abarcar los diferentes aspectos de la vida de una persona o una empresa, están ordenadas en diferentes apartados:
A8: 1.1 transporte
A9: 2.1. consumo energia en hogar'
A10: 3.1. dieta y consumo alimentos
A11: 4.1. Compras y consumos
A12: 5.1. Gestión de Residuos
A13: 6.1. Participación comunitaria
A15: Instrucciones:
... A24: Para cada acción, completa las siguientes columnas:
A26: ¿Puedo aplicarla? | E26: Indica si es posible aplicar la medida.
A27: Que % puedo aplicar | E27: Especifica el porcentaje de aplicación.
A28: En que periodo de tiempo puedo implementarla? | E28: Define el tiempo necesario para implementar la medida.
A29: Cuánto Carbono ( kg o % ) Creo que puedo evitar? | E29: Estima la cantidad de carbono que puedes evitar.
A30: Cuánto me va a costar? | E30: Calcula el costo asociado a la implementación.
A32: 3. "Cómo se Calcula"
A34: La hoja siguiente a cada hoja de acciones, lleva incorporado un ejemplo de calculo para cada acción, que te puede servir de orientación para tu calculo, Puedes usar la IA para facilitar el calculo de tu caso.
A35: La información de la hojas "Calcular …" te ayudaran a calcular las emisiones de carbono evitadas y el ahorro o coste que puede suponer su aplicación.
A37: 4. Creación de tu Plan Personal
A39: Una vez completadas cada una de las hojas, crea tu propio plan personal.
A40: Ordena la hoja completada poniendo en primer lugar aquellas medidas que puedes aplicar.
A41: En el menú: selecciona "Ordenar y filtrar" > "Orden personalizado".
A42: En el desplegable de la columna, elige "Columna F" > "Valores de celda" > "Orden Z-A".
A43: De esta manera, tendrás en primer lugar aquellas medidas que puedes aplicar.
A45: 5. Ordenar Medidas por Plazo de Aplicación
A47: Para ordenar las medidas por el plazo en que puedes aplicarlas, antes de cerrar el desplegable, selecciona "Añadir un nivel" > "Columna J" > "Valores de celda" > "Orden A-Z".
A48: Así, tendrás en primer lugar las medidas que puedes aplicar, ordenadas por corto, medio o largo plazo.
... A68: Periodicamente comprueba como va la implantación de las acciones que consideras realizables en la hoja "Mi Plan".

Sheet Índice 
B13: Nº de hoja | C13: Nombre | D13: Descripción | E13: Enlace
B14: 1 | C14: Cover | D14: Portada | E14: Cover!A1
B15: 2 | C15: Guia | D15: Breve explicación del uso de esta hoja de cálculo | E15: Guia!A1
B16: 3 | C16: Índice | D16: Índice | E16: Índice '!A1
B17: 4 | C17: Resumen de tu plan | D17: Resumen del impacto de las medidas seleccionadas en tu plan personal de reducción de huella de carbono. | E17: Resumen de tu plan'!A1
B18: 5 | C18: 1.1. Transporte | D18: Propuesta de acciones en materia de transporte para reducir la HC | E18: 1.1 transporte '!A1
B19: 6 | C19: 1.2. Calcular transporte | D19: Contiene indicaciones sobre el calculo de la reducción de la HC de las acciones de transporte | E19: 1.2. Calcular transporte'!A1
B20: 7 | C20: 2.1. Consumo energia en hogar | D20: Propuesta de acciones en materia de consumo de energia en el hogar para reducir la HC | E20: 2.1. consumo energia en hogar'!A1
B21: 8 | C21: 2.2. Calcular energia en hogar | D21: Contiene indicaciones sobre el calculo de la reducción de la HC de las acciones de consumo de energia en el hogar | E21: 2.2. Calcular Energia en hogar '!A1
B22: 9 | C22: 3.1. dieta y consumo alimentos | D22: Propuesta de acciones en materia de dieta y consumo de alimentos para reducir la HC | E22: 3.1. dieta y consumo alimentos'!A1
B23: 10 | C23: 3.2. calculo dieta y alimentos | D23: Contiene indicaciones sobre el calculo de la reducción de la HC de las acciones de dieta y consumo de alimentos | E23: 3.2. calculo dieta y alimentos'!A1
B24: 11 | C24: 4.1. Compras y consumos | D24: Propuesta de acciones en materia de Compras y consumos para reducir la HC | E24: 4.1. Compras y consumos'!A1
B25: 12 | C25: 4.2. Calcular compras y consumo | D25: Contiene indicaciones sobre el calculo de la reducción de la HC de las acciones de Compras y consumos | E25: 4.2. Calcular compras y consumo'!A1
... B31: 18 | C31: Mis ideas | D31: Vas a crear esta hoja con las ideas que consideras que puedes aplicar y no se hayan propuesto. | E31: Mis ideas'!A1
B32: 20 | C32: Anexo CO2 Spain | D32: Datos de emisión de CO2 en el día a día de una persona en España
B33: 21 | C33: Parametros | D33: Datos de las columnas del Plan con respuestas cerradas

Sheet Resumen de tu plan
B5: # | C5: Resumen del impacto de las medidas seleccionadas en tu plan personal de reducción de huella de carbono.
D6: Aplicabilidad en mi caso particular
D7: Si | E7: No | F7: Corto Plazo | G7: Medio Plazo | H7: Largo Plazo | I7: Coste Total | J7: Kg CO2
B8: 1 | C8: Transporte | D8: =COUNTIF('1.1 transporte '!E1:E41,"Si") -> 0 | E8: =COUNTIF('1.1 transporte '!E1:E41,"No") -> 0 | F8: =COUNTIF('1.1 transporte '!H1:H41,"Corto plazo ( 1 Mes o más )") -> 0 | G8: =COUNTIF('1.1 transporte '!H1:H41,"Medio plazo ( 3 Meses o más )") -> 0 | H8: =COUNTIF('1.1 transporte '!H1:H41,"Largo plazo ( 12 Meses o más )") -> 0 | I8: =SUM('1.1 transporte '!K3:K42) -> 0 | J8: =SUM('1.1 transporte '!I3:I42) -> 0
B9: 2 | C9: Consumo de Energía en el Hogar | D9: =COUNTIF('2.1. consumo energia en hogar'!E2:E56,"Si") -> 0 | E9: =COUNTIF('2.1. consumo energia en hogar'!F2:F56,"No") -> 0 | F9: =COUNTIF('2.1. consumo energia en hogar'!H1:H44,"Corto plazo ( 1 Mes o más )") -> 0 | G9: =COUNTIF('2.1. consumo energia en hogar'!H1:H44,"Medio plazo ( 3 Meses o más )") -> 0 | H9: =COUNTIF('2.1. consumo energia en hogar'!H1:H44,"Largo plazo ( 12 Meses o más )") -> 0 | I9: =SUM('2.1. consumo energia en hogar'!K3:K43) -> 0 | J9: =SUM('2.1. consumo energia en hogar'!I3:I43) -> 0
B10: 3 | C10: Dieta y Consumo de Alimentos | D10: =COUNTIF('3.1. dieta y consumo alimentos'!E3:E56,"Si") -> 0 | E10: =COUNTIF('3.1. dieta y consumo alimentos'!F3:F56,"No") -> 0 | F10: =COUNTIF('3.1. dieta y consumo alimentos'!H2:H35,"Corto plazo ( 1 Mes o más )") -> 0 | G10: =COUNTIF('3.1. dieta y consumo alimentos'!H2:H35,"Medio plazo ( 3 Meses o más )") -> 0 | H10: =COUNTIF('3.1. dieta y consumo alimentos'!H2:H35,"Largo plazo ( 12 Meses o más )") -> 0 | I10: =SUM('3.1. dieta y consumo alimentos'!K3:K32) -> 0 | J10: =SUM('3.1. dieta y consumo alimentos'!J3:J32) -> 0
B11: 4 | C11: Compras y Consumo | D11: =COUNTIF('4.1. Compras y consumos'!E4:E58,"Si") -> 0 | E11: =COUNTIF('4.1. Compras y consumos'!F4:F58,"No") -> 0 | F11: =COUNTIF('4.1. Compras y consumos'!H3:H66,"Corto plazo ( 1 Mes o más )") -> 0 | G11: =COUNTIF('4.1. Compras y consumos'!H3:H66,"Medio plazo ( 3 Meses o más )") -> 0 | H11: =COUNTIF('4.1. Compras y consumos'!H3:H66,"Largo plazo ( 12 Meses o más )") -> 0 | I11: =SUM('4.1. Compras y consumos'!K3:K51) -> 0 | J11: =SUM('4.1. Compras y consumos'!I3:I51) -> 0
B12: 5 | C12: Gestión de Residuos | D12: =COUNTIF('5.1. Gestión de Residuos '!E2:E56,"Si") -> 0 | E12: =COUNTIF('5.1. Gestión de Residuos '!F2:F56,"No") -> 0 | F12: =COUNTIF('5.1. Gestión de Residuos '!H51,"Corto plazo ( 1 Mes o más )") -> 0 | G12: =COUNTIF('5.1. Gestión de Residuos '!H51,"Medio plazo ( 3 Meses o más )") -> 0 | H12: =COUNTIF('5.1. Gestión de Residuos '!H51,"Largo plazo ( 12 Meses o más )") -> 0 | I12: =SUM('5.1. Gestión de Residuos '!K3:K41) -> 0 | J12: =SUM('5.1. Gestión de Residuos '!I3:I41) -> 0
B13: 6 | C13: Participación Comunitaria y Conciencia Ambiental | D13: =COUNTIF('6.1. Participación comunitaria'!F2:F35,"Si") -> 0 | E13: =COUNTIF('6.1. Participación comunitaria'!G2:G35,"No") -> 0 | F13: =COUNTIF('6.1. Participación comunitaria'!L41,"Corto plazo ( 1 Mes o más )") -> 0 | G13: =COUNTIF('6.1. Participación comunitaria'!L41,"Medio plazo ( 3 Meses o más )") -> 0 | H13: =COUNTIF('6.1. Participación comunitaria'!L41,"largo plazo ( 12 Meses o más )") -> 0 | I13: =SUM('6.1. Participación comunitaria'!L3:L34) -> 0 | J13: =SUM('6.1. Participación comunitaria'!I3:I34) -> 0
C15: Total | D15: =SUM(D8:D14) -> 0 | E15: =SUM(E8:E14) -> 0 | F15: =SUM(F8:F14) -> 0 | G15: =SUM(G8:G14) -> 0 | H15: =SUM(H8:H14) -> 0 | I15: =SUM(I8:I14) -> 0 | J15: =SUM(J8:J14) -> 0

Sheet 1.1 transporte  
A1: Acciónes del Grupo de Transporte | B1: Acción nº | C1: Descripción | D1: Impacto Potencial | E1: Puedo Aplicarla? | F1: Que % puedo aplicar | G1: Facilidad de Ejecución | H1: En que periodo de tiempo puedo implementarla ? | I1: Cuánto Carbono ( kg o % ) Creo que puedo evitar / ahorrar / quitar? | J1: Coste | K1: Cuánto me va a costar? ( Indique €uros Anuales ) | L1: Duración | M1: Rol (Ciudadano, Empleado, Familia, Amigos, Comunidad)
A2: Organización y Planificación del Transporte Personal
A3: Planificar rutas eficientes | B3: 1 | C3: Planificar viajes para minimizar la distancia y el tiempo en carretera | D3: Moderado | G3: Fácil | I3: 0 | J3: Ninguno | L3: Continuo | M3: Ciudadano
A4: Usar aplicaciones de transporte público | B4: 2 | C4: Utilizar aplicaciones para acceder a horarios y rutas de transporte público | D4: Moderado | G4: Fácil | I4: 0 | J4: Bajo | L4: Continuo | M4: Ciudadano
A5: Participar en programas de incentivos para el transporte público | B5: 3 | C5: Utilizar programas de descuento para fomentar el transporte público | D5: Moderado | G5: Fácil | I5: 0 | J5: Variable | L5: Continuo | M5: Ciudadano, Empleado
A6: Utilizar aplicaciones de navegación con tráfico en tiempo real | B6: 4 | C6: Evitar atascos y rutas congestionadas | D6: Moderado | G6: Fácil | I6: 0 | J6: Bajo | L6: Continuo | M6: Ciudadano
A7: Mantener un automóvil bien mantenido | B7: 5 | C7: Realizar un mantenimiento regular para mejorar la eficiencia | D7: Moderado | G7: Moderado | I7: 0 | J7: Variable | L7: Continuo | M7: Ciudadano
A8: Utilizar neumáticos de baja resistencia. | B8: 6 | C8: Emplear neumáticos que reduzcan la resistencia al rodamiento para mejorar la eficiencia de combustible. | D8: Moderado | G8: Fácil | I8: 0 | J8: Variable | L8: Continuo | M8: Ciudadano
A9: Rellenar las ruedas de tu vehículo con nitrógeno. | B9: 7 | C9: Mejorar el rendimiento del combustible y la duración de los neumáticos. | D9: Moderado | G9: Fácil | I9: 0 | J9: Variable | L9: Continuo | M9: Ciudadano
A10: Evitar la conducción agresiva | B10: 8 | C10: Conducir de manera más suave y eficiente para reducir el consumo de combustible | D10: Moderado | G10: Fácil | I10: 0 | J10: Ninguno | L10: Continuo | M10: Ciudadano
A11: Evitar viajes innecesarios | B11: 9 | C11: Reducir los viajes personales que no sean esenciales | D11: Moderado | G11: Fácil | I11: 0 | J11: Ninguno | L11: Continuo | M11: Ciudadano
A12: Implementar un sistema de transporte al trabajo | B12: 10 | C12: Organizar viajes compartidos para empleados | D12: Alto | G12: Moderado | I12: 0 | J12: Variable | L12: Continuo | M12: Empleado
A13: Crear un diario de emisiones. | B13: 11 | C13: Mantener un registro diario de tus viajes y sus emisiones para identificar áreas de mejora. | D13: Moderado | G13: Fácil | I13: 0 | J13: Ninguno | L13: Continuo | M13: Ciudadano
A14: Realizar un plan de movilidad semanal. | B14: 12 | C14: Planificar y combinar viajes para reducir el número total de desplazamientos necesarios. | D14: Moderado | G14: Moderado | I14: 0 | J14: Ninguno | L14: Continuo | M14: Ciudadano
A15: Transporte Público
A16: Usar transporte público | B16: 13 | C16: Optar por autobuses, trenes o metros en lugar de automóvil personal | D16: Alto | G16: Moderado | I16: 0 | J16: Variable | L16: Continuo | M16: Ciudadano
A17: Adoptar un “Día del Transporte Público”. | B17: 14 | C17: Designar un día semanal para usar únicamente transporte público. | D17: Alto | G17: Moderado | I17: 0 | J17: Ninguno | L17: Continuo | M17: Ciudadano
A18: Invertir en opciones de transporte público ecológicas | B18: 15 | C18: Promover la inversión en transporte público sostenible | D18: Alto | G18: Moderado | I18: 0 | J18: Variable | L18: Continuo | M18: Ciudadano, Comunidad
A19: Apoyar la creación de carriles exclusivos para autobuses | B19: 16 | C19: Abogar por carriles dedicados a autobuses para fomentar el transporte público | D19: Moderado | G19: Moderado | I19: 0 | J19: Variable | L19: Continuo | M19: Ciudadano, Comunidad
A20: Utilización combinada de transporte público-transporte privado ( intermodal ) | B20: 17 | C20: Buscar estaciones de recarga para vehículos eléctricos en estaciones de transporte públicos y combinar medios de transporte | D20: Moderado | G20: Moderado | I20: 0 | J20: Ninguno | L20: Continuo | M20: Ciudadano
A21: Transporte Compartido
A22: Compartir viajes (carpooling) | B22: 18 | C22: Compartir el automóvil con colegas o amigos para reducir emisiones | D22: Moderado | G22: Fácil | I22: 0 | J22: Variable | L22: Continuo | M22: Ciudadano, Amigos
A23: Fomentar el uso del taxi compartido. | B23: 19 | C23: Compartir viajes en taxi con otros usuarios para reducir las emisiones por pasajero. | D23: Moderado | G23: Moderado | I23: 0 | J23: Variable | L23: Continuo | M23: Ciudadano
A24: Desarrollar zonas de encuentro para compartir coches. | B24: 20 | C24: Crear puntos especificos para facilitar el uso compartido de vehículos entre personas. | D24: Moderado | G24: Moderado | I24: 0 | J24: Variable | L24: Continuo | M24: Comunidad
A25: Usar vehículos compartidos (carsharing) | B25: 21 | C25: Alquilar vehículos solo cuando sea necesario | D25: Moderado | G25: Fácil | I25: 0 | J25: Variable | L25: Continuo | M25: Ciudadano
A26: Utilizar servicios de transporte compartido | B26: 22 | C26: Utilizar servicios como UberPool o Lyft Line | D26: Moderado | G26: Fácil | I26: 0 | J26: Variable | L26: Continuo | M26: Ciudadano
A27: Vehículos Personales
A28: Optar por vehículos eléctricos o híbridos | B28: 23 | C28: Comprar un automóvil eléctrico o híbrido | D28: Alto | G28: Moderado | I28: 0 | J28: Variable | L28: A largo plazo | M28: Ciudadano, Familia
A29: Elegir automóviles con alta eficiencia de combustible | B29: 24 | C29: Comprar vehículos con un bajo consumo de combustible | D29: Moderado | G29: Moderado | I29: 0 | J29: Variable | L29: A largo plazo | M29: Ciudadano, Familia
A30: Evitar el uso de vehículos todo terreno | B30: 25 | C30: Optar por vehículos más eficientes en combustible | D30: Moderado | G30: Moderado | I30: 0 | J30: Variable | L30: Continuo | M30: Ciudadano
A31: Transporte No Motorizado
A32: Promover el uso de transportes no motorizados | B32: 26 | C32: Fomentar el uso de caminar o patinetas eléctricas | D32: Moderado | G32: Fácil | I32: 0 | J32: Bajo | L32: Continuo | M32: Ciudadano, Comunidad
A33: Fomentar el uso de bicicletas | B33: 27 | C33: Promover el ciclismo como medio de transporte | D33: Moderado | G33: Fácil | I33: 0 | J33: Bajo | L33: Continuo | M33: Ciudadano, Comunidad
A34: Apoyar la infraestructura para bicicletas | B34: 28 | C34: Abogar por más carriles para bicicletas y estacionamientos | D34: Moderado | G34: Moderado | I34: 0 | J34: Variable | L34: Continuo | M34: Ciudadano, Comunidad
A35: Alternativas al Transporte
A36: Trabajar desde casa o teletrabajar | B36: 29 | C36: Realizar el trabajo desde casa para evitar viajes diarios | D36: Moderado | G36: Fácil | I36: 0 | J36: Variable | L36: Continuo | M36: Empleado, Ciudadano
A37: Caminar | B37: 30 | C37: Utilizar caminatas en lugar de transportes motorizados para distancias cortas. | D37: Moderado | G37: Fácil | I37: 0 | J37: Ninguno | L37: Continuo | M37: Ciudadano
A38: Otras Acciones
A39: Contribuir a proyectos de movilidad sostenible | B39: 31 | C39: Apoyar proyectos comunitarios de movilidad sostenible | D39: Alto | G39: Moderado | I39: 0 | J39: Variable | L39: Continuo | M39: Ciudadano, Comunidad
A40: Sustituir el uso del avión por otros transportes. | B40: 32 | C40: Optar por medios de transporte con menor volumen de emisiones: tren, barco, autobuses, etc. en lugar de vuelos cortos. | D40: Alto | G40: Moderado | I40: 0 | J40: Variable | L40: Continuo | M40: Ciudadano, Comunidad
...

Sheet 1.2. Calcular transporte
B1: Acciones del grupo de Transporte | C1: Como se calcula la reducción al realizar la acción | D1: Notas personales
B2: Organización y Planificación del Transporte Personal
A3: 1 | B3: Planificar rutas eficientes | C3: Reducción en kms X factor de emisión del vehículo (g CO2/km)
A4: 2 | B4: Usar aplicaciones de transporte público | C4: Kms automóvil sustituidos por transporte público X (emisiones transporte privado - emisiones transporte público)
A5: 3 | B5: Participar en programas de incentivos para el transporte público | C5: Como en el anterior, medir los viajes que se sustituyen por transporte público y calcular la diferencia de emisiones
A6: 4 | B6: Utilizar aplicaciones de navegación con tráfico en tiempo real | C6: Medir la reducción del tiempo de viaje y de combustible al evitar tráfico. Usar el consumo promedio de combustible con tráfico y sin tráfico.
A7: 5 | B7: Mantener un automóvil bien mantenido | C7: Entre un 5% y 10% menos de combustible. Estima la mejora en eficiencia de combustible (l/100 km) y multiplíca por los kms recorridos.
A8: 6 | B8: Utilizar neumáticos de baja resistencia. | C8: Pueden reducir el consumo entre un 3% y 5%. Con este porcentaje calcula la reducción en emisiones.
A9: 7 | B9: Rellenar las ruedas de tu vehículo con nitrógeno. | C9: Una presión correcta ahorra un 1-3% de combustible, reduciendo las emisiones proporcionalmente.
A10: 8 | B10: Evitar la conducción agresiva | C10: La conducción suave reduce el consumo de combustible hasta un 30%, calcula el ahorro en función de los kilómetros recorridos.
A11: 9 | B11: Evitar viajes innecesarios | C11: Suma los kilómetros evitados y multiplícalo por las emisiones por km del vehículo.
A12: 10 | B12: Implementar un sistema de transporte al trabajo | C12: Calcula la reducción en viajes y su impacto en emisiones al compartir coche.
A13: 11 | B13: Crear un diario de emisiones. | C13: No tiene reducción directa, pero ayuda a identificar hábitos para optimizar la movilidad y reducir la huella.
A14: 12 | B14: Realizar un plan de movilidad semanal. | C14: Similar al diario, facilita la planificación para reducir viajes innecesarios y ahorrar combustible.
B15: Transporte Público
A16: 13 | B16: Usar transporte público | C16: Calcula los viajes que se sustituyen por transporte público y calcular la diferencia de emisiones
A17: 14 | B17: Adoptar un “Día del Transporte Público”. | C17: Similar a usar transporte público, calcula las emisiones evitadas en ese día.
A18: 15 | B18: Invertir en opciones de transporte público ecológicas | C18: Se mide a largo plazo con la eficiencia energética de los nuevos vehículos.
A19: 16 | B19: Apoyar la creación de carriles exclusivos para autobuses | C19: Optimiza el tiempo y combustible del transporte público, pero requiere datos locales para medirlo.
A20: 17 | B20: Utilización combinada de transporte público-transporte privado ( intermodal ) | C20: Medir la diferencia en kilómetros recorridos respecto al uso exclusivo de vehículos privados
B21: Transporte Compartido
A22: 18 | B22: Compartir viajes (carpooling) | C22: Multiplica los kilómetros ahorrados por el número de pasajeros y calcula la reducción en emisiones.
A23: 19 | B23: Fomentar el uso del taxi compartido. | C23: Similar al carpooling, mide la diferencia en viajes individuales y calcula las emisiones evitadas.
A24: 20 | B24: Desarrollar zonas de encuentro para compartir coches. | C24: Se debe medir la reducción en desplazamientos individuales mediante la reducción de viajes solitarios.
A25: 21 | B25: Usar vehículos compartidos (carsharing) | C25: Similar al carpooling, mide la diferencia en viajes individuales y calcula las emisiones evitadas.
A26: 22 | B26: Utilizar servicios de transporte compartido | C26: Similar al carpooling, mide la diferencia en viajes individuales y calcula las emisiones evitadas.
B27: Vehículos Personales
A28: 23 | B28: Optar por vehículos eléctricos o híbridos | C28: Calcula las emisiones evitadas en base a la comparación con un vehículo de combustión.
A29: 24 | B29: Elegir automóviles con alta eficiencia de combustible | C29: Estima el ahorro de combustible por km recorrido y calcula la reducción de CO2.
A30: 25 | B30: Evitar el uso de vehículos todo terreno | C30: Calcula las emisiones evitadas usando un vehículo más eficiente.
B31: Transporte No Motorizado
A32: 26 | B32: Promover el uso de transportes no motorizados | C32: No tiene reducción directa, pero ayuda a modificar hábitos para optimizar la movilidad y reducir la huella.
A33: 27 | B33: Fomentar el uso de bicicletas | C33: Calcula los kilómetros en bicicleta y las emisiones evitadas al no usar un automóvil.
A34: 28 | B34: Apoyar la infraestructura para bicicletas | C34: No tiene reducción directa, pero ayuda a modificar hábitos para optimizar la movilidad y reducir la huella.
B35: Alternativas al Transporte
A36: 29 | B36: Trabajar desde casa o teletrabajar | C36: Calcula los kms evitados y multiplícalo por las emisiones por km del vehículo.
A37: 30 | B37: Caminar | C37: Calcula los kms evitados y multiplícalo por las emisiones por km del vehículo.
B38: Otras Acciones
A39: 31 | B39: Contribuir a proyectos de movilidad sostenible | C39: No tiene reducción directa, pero ayuda a optimizar la movilidad y reducir la huella.
A40: 32 | B40: Sustituir el uso del avión por otros transportes. | C40: Calcula las emisiones evitadas comparando el viaje en avión con barco, tren o autobús.
...

Sheet 2.1. consumo energia en hogar
A1: Acciones del grupo Consumo de Energía en el Hogar | B1: Acción nº | C1: Descripción | D1: Impacto Potencial | E1: Puedo Aplicarla? | F1: Que % puedo aplicar | G1: Facilidad de Ejecución | H1: En que periodo de tiempo puedo implementarla ? | I1: Cuánto Carbono ( kg o % ) Creo que puedo evitar / ahorrar / quitar? | J1: Coste | K1: Cuánto me va a costar? ( Indique €uros Anuales ) | L1: Duración | M1: Rol (Ciudadano, Empleado, Familia, Amigos, Comunidad)
A2: Organización y Planificación del Consumo de Energía
A3: Realizar auditoría energética | B3: 1 | C3: Evaluar el consumo de energía en el hogar y tomar medidas eficientes | D3: Alto | G3: Moderado | I3: 0 | J3: Variable | L3: Continuo | M3: Ciudadano, Familia
A4: Apagar la computadora cuando no se usa | B4: 2 | C4: Evitar dejar la computadora encendida en modo espera | D4: Bajo | G4: Fácil | I4: 0 | J4: Ninguno | L4: Continuo | M4: Ciudadano
A5: Apagar el monitor cuando no se use la computadora (activar el save energy) | B5: 3 | C5: Reducir el consumo de energía de la computadora | D5: Bajo | G5: Fácil | I5: 0 | J5: Ninguno | L5: Continuo
A6: Apagar luces al salir de una habitación | B6: 4 | C6: Reducir el consumo eléctrico al no usar la iluminación | D6: Bajo | G6: Fácil | I6: 0 | J6: Ninguno | L6: Continuo | M6: Ciudadano
A7: Apagar dispositivos no esenciales | B7: 5 | C7: Desconectar cargadores y dispositivos cuando no se usan | D7: Bajo | G7: Fácil | I7: 0 | J7: Ninguno | L7: Continuo | M7: Ciudadano
A8: Apagar dispositivos en stand-by | B8: 6 | C8: Desconectar dispositivos electrónicos cuando no se usan | D8: Moderado | G8: Fácil | I8: 0 | J8: Ninguno | L8: Continuo | M8: Ciudadano
A9: Implementar sistemas de automatización del hogar | B9: 7 | C9: Automatizar la gestión de energía en el hogar (luces, calefacción, etc.) | D9: Moderado | G9: Moderado | I9: 0 | J9: Variable | L9: Continuo | M9: Ciudadano, Familia
A10: Informarse sobre tarifas energéticas más económicas | B10: 8 | C10: Comparar tarifas y cambiar a la más eficiente. | D10: Bajo | G10: Fácil | I10: 0 | J10: Ninguno | L10: Continuo | M10: Ciudadano
A11: Eficiencia Energética
A12: Utilizar electrodomésticos con eficiencia energética | B12: 9 | C12: Elegir dispositivos que cumplan con estándares de eficiencia | D12: Moderado | G12: Fácil | I12: 0 | J12: Variable | L12: Continuo | M12: Ciudadano
A13: Usar electrodomésticos fuera de las horas pico | B13: 10 | C13: Consumir energía en momentos de menor demanda | D13: Moderado | G13: Fácil | I13: 0 | J13: Ninguno | L13: Continuo | M13: Ciudadano
A14: Descongelar alimentos antes de cocinar | B14: 11 | C14: Reducir el tiempo de cocción y el consumo de energía | D14: Bajo | G14: Fácil | I14: 0 | J14: Ninguno | L14: Continuo | M14: Ciudadano, Familia
A15: Limitar el uso del horno | B15: 12 | C15: Optar por métodos de cocción más eficientes | D15: Bajo | G15: Fácil | I15: 0 | J15: Ninguno | L15: Continuo | M15: Ciudadano, Familia
A16: Evitar la apertura frecuente del horno | B16: 13 | C16: Cocinar varios alimentos a la vez para reducir ciclos de calentamiento | D16: Bajo | G16: Fácil | I16: 0 | J16: Ninguno | L16: Continuo | M16: Ciudadano, Familia
A17: Usar bombillas LED | B17: 14 | C17: Reemplazar bombillas incandescentes por LED | D17: Moderado | G17: Fácil | I17: 0 | J17: Moderado | L17: Continuo | M17: Ciudadano
A18: Utilizar iluminación natural | B18: 15 | C18: Aprovechar la luz natural durante el día en lugar de luces artificiales | D18: Bajo | G18: Fácil | I18: 0 | J18: Ninguno | L18: Continuo | M18: Ciudadano
A19: Mejorar el aislamiento | B19: 16 | C19: Aislar ventanas y puertas para conservar la temperatura y mejorar eficiencia energetica | D19: Alto | G19: Moderado | I19: 0 | J19: Variable | L19: Continuo | M19: Ciudadano, Familia
A20: Utilizar cortinas térmicas | B20: 17 | C20: Regulación de la temperatura de la habitación con cortinas adecuadas | D20: Moderado | G20: Fácil | I20: 0 | J20: Variable | L20: Continuo | M20: Ciudadano, Familia
A21: Cerrar puertas y ventanas al usar calefacción o aire acondicionado | B21: 18 | C21: Evitar pérdida de calor o frío en la casa | D21: Moderado | G21: Fácil | I21: 0 | J21: Ninguno | L21: Continuo | M21: Ciudadano
A22: Utilizar regletas con interruptor para cortar el suministro eléctrico | B22: 19 | C22: Evitar consumo en stand-by. | D22: Bajo | G22: Fácil | I22: 0 | J22: Bajo | L22: Continuo | M22: Ciudadano.
A23: Energías Renovables
A24: Instalar paneles solares | B24: 20 | C24: Generar electricidad a partir de energía solar en el hogar | D24: Alto | G24: Moderado | I24: 0 | J24: Moderado | L24: A largo plazo | M24: Ciudadano, Familia
A25: Utilizar energía renovable | B25: 21 | C25: Comprar electricidad de fuentes renovables si está disponible | D25: Moderado | G25: Fácil | I25: 0 | J25: Variable | L25: Continuo | M25: Ciudadano
A26: Utilizar calentador de agua solar | B26: 22 | C26: Calentar agua con energía solar en lugar de electricidad | D26: Alto | G26: Moderado | I26: 0 | J26: Moderado | L26: A largo plazo | M26: Ciudadano, Familia
A27: Cambiar de compañía eléctica a una 100% renovable | B27: 23 | C27: Contratar electricidad verde. | D27: Alto | G27: Fácil | I27: 0 | J27: Variable | L27: Continuo | M27: Ciudadano, Familia.
A28: Calefacción y Refrigeración
A29: Reducir la temperatura del calentador de agua | B29: 24 | C29: Bajar la temperatura del calentador para ahorrar energía | D29: Moderado | G29: Fácil | I29: 0 | J29: Ninguno | L29: Continuo | M29: Ciudadano, Familia
A30: Instalar termostatos programables / Termometro de estancia | B30: 25 | C30: Controlar la calefacción y el aire acondicionado de manera eficiente | D30: Moderado | G30: Fácil | I30: 0 | J30: Variable | L30: Continuo | M30: Ciudadano
A31: Programar el termostato en invierno ( aspecto legal en empresas - 26º) | B31: 26 | C31: Reducir la temperatura cuando no estés en casa | D31: Moderado | G31: Fácil | I31: 0 | J31: Ninguno | L31: Continuo | M31: Ciudadano
A32: Usar ventiladores en lugar de aire acondicionado cuando sea posible | B32: 27 | C32: Reducir el consumo energético en refrigeración. | D32: Moderado | G32: Fácil | I32: 0 | J32: Ninguno | L32: Continuo | M32: Ciudadano.
A33: Programar el termostato en verano ( aspecto legal en empresas - 21º) | B33: 28 | C33: Aumentar la temperatura cuando no estés en casa | D33: Moderado | G33: Fácil | I33: 0 | J33: Ninguno | L33: Continuo | M33: Ciudadano
A34: Eficiencia en actividades domésticas.
A35: Instalar cabezales de ducha y grifos de bajo flujo | B35: 29 | C35: Reducir el consumo de agua en el hogar. | D35: Moderado | G35: Fácil | I35: 0 | J35: Variable | L35: Continuo | M35: Ciudadano, Familia.
A36: Reparar fugas de agua rápidamente | B36: 30 | C36: Evitar el desperdicio de agua en el hogar | D36: Moderado | G36: Fácil | I36: 0 | J36: Bajo | L36: Continuo | M36: Ciudadano, Familia.
A37: Cocinar con ollas de presión y de cocción lenta | B37: 31 | C37: Ahorrar energía en la cocina. | D37: Moderado | G37: Fácil | I37: 0 | J37: Ninguno | L37: Continuo | M37: Ciudadano, Familia.
A38: Utilizar la freidora de aire en lugar del horno cuando sea posible | B38: 32 | C38: Cocinar con menos energía. | D38: Moderado | G38: Fácil | I38: 0 | J38: Ninguno | L38: Continuo | M38: Ciudadano.
A39: Mantener las puertas del refrigerador cerradas y en buen estado | B39: 33 | C39: Mejorar la eficiencia del electrodoméstico. | D39: Moderado | G39: Fácil | I39: 0 | J39: Ninguno | L39: Continuo | M39: Ciudadano.
A40: Lavar la ropa con agua fría siempre que sea posible ( y durará más ) | B40: 34 | C40: Ahorrar energía en el lavado de ropa. | D40: Moderado | G40: Fácil | I40: 0 | J40: Ninguno | L40: Continuo | M40: Ciudadano.
...

Sheet 2.2. Calcular energía en el hog
B1: Acciones del grupo Consumo de Energía en el Hogar | C1: Como se calcula la reducción al realizar la acción | D1: Notas personales
B2: Organización y Planificación del Consumo de Energía
A3: 1 | B3: Realizar auditoría energética | C3: Es el primer paso para identificar mejoras en eficiencia energética, pero no reduce emisiones.
A4: 2 | B4: Apagar la computadora cuando no se usa | C4: Encendida sin uso: N horas/día * 365 días/año * 100 W / 1000 = X kWh. Apagada y enchufada: N horas/día * 365 días/año * 5 W / 1000 = Y kWh. | D4: Para calcular CO2 emitido en ambos casos multiplicar por F. conversión 0,18. Ver la diferencia. En € multiplicar Kwh por 0,122 €/Kwh
A5: 3 | B5: Apagar el monitor cuando no se use la computadora (activar el save energy) | C5: Si un monitor consume 30 W y se apaga 1 hora al día: 30 W * 1 hora/día * 365 días/año / 1000 = 10.95 kWh. | D5: CO₂ evitado: 10.95 kWh * 0.18 = 1.97 kg CO₂. En €: 10.95 kWh * 0.122 €/kWh = 1.33 €.
A6: 4 | B6: Apagar luces al salir de una habitación | C6: Igual que en el caso anterior, si apagas una luz de 30 W durante 1 hora/día: CO₂ evitado: 10.95 kWh * 0.18 = 1.97 kg CO₂ y supone un ahorro 10.95 kWh * 0.122 €/kWh = 1.33 €.
A7: 5 | B7: Apagar dispositivos no esenciales | C7: Si estos dispositivos consumen 30w en una hora al día, igual que el anterior
A8: 6 | B8: Apagar dispositivos en stand-by | C8: Consumo ahorrado (kWh): Z kWh/año. CO₂ evitado: Z kWh * 0.18 = 0,18Z kg CO₂. Ahorro: Z kWh * 0.122 €/kWh = 0,122Z €.
A9: 7 | B9: Implementar sistemas de automatización del hogar | C9: Id anterior
A10: 8 | B10: Informarse sobre tarifas energéticas más económicas
B11: Eficiencia Energética
A12: 9 | B12: Utilizar electrodomésticos con eficiencia energética | C12: Consumo ahorrado (kWh): Z kWh/año. CO₂ evitado: Z kWh * 0.18 = 0,18Z kg CO₂. Ahorro: Z kWh * 0.122 €/kWh = 0,122Z €.
A13: 10 | B13: Usar electrodomésticos fuera de las horas pico | C13: No genera una reducción directa de emisiones de CO₂, pero mejora la eficiencia de la red.
A14: 11 | B14: Descongelar alimentos antes de cocinar | C14: Si reduce el uso del horno en 1h, 2000 W * 1 hora = 2 kWh. CO₂ evitado: 2 kWh * 0.18 = 0.36 kg CO₂. Ahorro: 2 kWh * 0.122 €/kWh = 0.24 €.
A15: 12 | B15: Limitar el uso del horno | C15: Similar al anterior, teniendo en cuenta el tiempo de reducción.
A16: 13 | B16: Evitar la apertura frecuente del horno | C16: Reducir ciclos de calentamiento, no genera un cálculo exacto pero el ahorro sería similar a limitar el uso
A17: 14 | B17: Usar bombillas LED | C17: Compara una bombilla incandescente (100 W) frente a una LED (15 W), 3 h/día. Incandescente: 100 W * 3 h/d * 365/ 1000 = 109.5 kWh/año. LED (15W) = 16.42 kWh/año. Diferencia: 93.08 kWh/año. CO₂ evitado: 93.08 * 0.18 = 16.75 kg CO₂.: 93.08 * 0.122 €/kWh = 11.36 €.
A18: 15 | B18: Utilizar iluminación natural | C18: Similar al anterior, teniendo en cuenta el tiempo de reducción.
A19: 16 | B19: Mejorar el aislamiento | C19: Depende de las mejoras, puede reducir el uso de calefacción y aire acondicionado en 500-1000 kWh/año.
A20: 17 | B20: Utilizar cortinas térmicas | C20: Las cortinas térmicas ayudan a mantener la temperatura interna, lo que puede reducir la climatización en un 5-10% en climas moderados.
A21: 18 | B21: Cerrar puertas y ventanas al usar calefacción o aire acondicionado | C21: Similar a mejorar el aislamiento.
A22: 19 | B22: Utilizar regletas con interruptor para cortar el suministro eléctrico | C22: Determina la energía (en kWh) utilizada al año en calefacción o refrigeración. Aplica el 5-10% de reducción al consumo total. Multiplica los kwh/año obtenidos por 0,18 y 0,122 para saber CO" evitados y ahorro
B23: Energías Renovables
A24: 20 | B24: Instalar paneles solares | C24: Depende de su capacidad. Si sustituimos la electricidad de la red (0.18 kg CO₂/kWh), podrías evitar hasta 1000 kg de CO₂ al año.El ahorro dependerá del porcentaje de la energía solar utilizada .
A25: 21 | B25: Utilizar energía renovable | C25: Si toda tu electricidad proviene de fuentes renovables, eliminas el 100% de las emisiones de tu consumo eléctrico, el factor de emisión de energía renovable es cero.
A26: 22 | B26: Utilizar calentador de agua solar | C26: Si el calentador solar sustituye el 100% del consumo eléctrico, podrías evitar todo el CO₂ emitido en este concepto (0,18 factor de emisión).
A27: 23 | B27: Cambiar de compañía eléctica a una 100% renovable | C27: Similar al uso de energia renovable
B28: Calefacción y Refrigeración
A29: 24 | B29: Reducir la temperatura del calentador de agua | C29: Calcula los kwh que puedes evitar al reducir la temperatura unos grados. Usando el factor de emisión (0.18 kg CO₂/kWh), obtienes los kg CO₂ evitados. El ahorro sería ( kWh evitados * 0.122 €/kWh).
A30: 25 | B30: Instalar termostatos programables / Termometro de estancia | C30: Los termostatos programables pueden reducir el consumo de calefacción o aire acondicionado en un 10-20%. Si tu consumo es de 1500-2000 kWh al año, un ahorro del 10% significaría 150-200 kWh. hasta 150 kg CO₂ y un ahorro de 91.50 € al año.
A31: 26 | B31: Programar el termostato en invierno ( aspecto legal en empresas - 26º) | C31: Cálculo similar al anterior.
A32: 27 | B32: Usar ventiladores en lugar de aire acondicionado cuando sea posible | C32: Un ventilador consume aprox. 50 W frente a los 1000 W de un aire acondicionado. Si lo usas 4 horas al día 100 días, ahorras 380 kWh, una reducción de 15-30 kg CO₂ y un ahorro de hasta 18 €.
A33: 28 | B33: Programar el termostato en verano ( aspecto legal en empresas - 21º) | C33: Similar a instalar termostatos programables
B34: Eficiencia en actividades domésticas.
A35: 29 | B35: Instalar cabezales de ducha y grifos de bajo flujo | C35: Reduce aprox. 15-30% de calefacción de agua.
A36: 30 | B36: Reparar fugas de agua rápidamente | C36: Depende. Ahorra energía y agua al evitar un uso innecesario.
A37: 31 | B37: Cocinar con ollas de presión y de cocción lenta | C37: Ahorro energético de 50-70% respecto a hornos.
A38: 32 | B38: Utilizar la freidora de aire en lugar del horno cuando sea posible | C38: Ahorra 50-80% de energía en comparación con el horno.
A39: 33 | B39: Mantener las puertas del refrigerador cerradas y en buen estado | C39: Evita pérdidas de energía en refrigeración.
A40: 34 | B40: Lavar la ropa con agua fría siempre que sea posible ( y durará más ) | C40: En cada ciclo de lavado aprox. 0.5 kWh de ahorro.
...

Sheet 3.1. dieta y consumo alimentos
A1: Acciones del grupo Dieta y consumo de alimentos | B1: Acción nº | C1: Descripción | D1: Impacto Potencial | E1: Puedo Aplicarla? | F1: Que % puedo aplicar | G1: Facilidad de Ejecución | H1: En que periodo de tiempo puedo implementarla ? | I1: Cuánto Carbono ( kg o % ) Creo que puedo evitar / ahorrar / quitar? | J1: Coste | K1: Cuánto me va a costar? ( Indique €uros Anuales ) | L1: Duración | M1: Rol (Ciudadano, Empleado, Familia, Amigos, Comunidad)
A2: Políticas de Consumo
A3: Busca cooperativas de consumo en tu barrio | B3: 1 | C3: Participar en cooperativas puede reducir el desperdicio y apoyar el consumo local. | D3: Medio | G3: media | I3: 0 | J3: Ninguno | L3: Continua | M3: Ciudadano
A4: Usar apps para evitar el desperdicio de alimentos | B4: 2 | C4: Aplicaciones como Too Good To Go o Olio para comprar excedentes de alimentos a bajo costo y evitar el desperdicio. | D4: Bajo | G4: Fácil | I4: 0 | J4: Ninguno | L4: Continua | M4: Ciudadano
A5: Apoyar iniciativas locales de reducción de desperdicios | B5: 3 | C5: Involucrarse en programas y campañas que promuevan la reducción de residuos alimentarios en la comunidad. | D5: Medio | G5: media | I5: 0 | J5: Ninguno | L5: Continua | M5: Ciudadano, familia, amigos, comunidad
A6: Educar y concienciar. | B6: 5 | C6: Informar a familiares y amigos sobre la importancia de reducir la huella de carbono en el consumo de alimentos. | D6: Medio | G6: media | I6: 0 | J6: Ninguno | L6: Continua | M6: Ciudadano, familia, amigos, comunidad
A7: Involucrarse en políticas alimentarias. | B7: 6 | C7: Participar en movimientos y organizaciones que promuevan políticas alimentarias sostenibles a nivel local y nacional | D7: Bajo | G7: Fácil | I7: 0 | J7: Ninguno | L7: Continua | M7: Ciudadano
A8: Dieta y Alimentación
A9: Limitar el consumo de carne, especialmente de carne de vacuno | B9: 7 | C9: Reducir el consumo de carne, especialmente de carne de vacuno, que tiene una huella de carbono más alta que otros tipos de carne. | D9: Medio | G9: Fácil | I9: 0 | J9: Bajo | L9: Permanente | M9: Ciudadano, familia, amigos, comunidad
A10: Reducir el consumo de lácteos | B10: 8 | C10: Disminuir la ingesta de productos lácteos | D10: Medio | G10: Media | I10: 0 | J10: Variable | L10: Continuo | M10: Ciudadano, Familia
A11: Reducir alimentos procesados | B11: 9 | C11: Evitar alimentos con excesivo procesamiento | D11: Medio | G11: Media | I11: 0 | J11: Bajo | L11: Continuo | M11: Ciudadano
A12: Evitar comidas rápidas | B12: 10 | C12: Preferir comidas caseras y saludables | D12: Medio | G12: Alta | I12: 0 | J12: Bajo | L12: Continuo | M12: Ciudadano, Familia
A13: Consumir porciones adecuadas | B13: 11 | C13: Evitar el exceso en las comidas | D13: Bajo | G13: Alta | I13: 0 | J13: Ninguno | L13: Continuo | M13: Ciudadano, Familia
A14: Consumir pescado obtenido mediante pesca sostenible | B14: 12 | C14: Elegir pescado que se ha capturado de forma sostenible, evitando las especies en peligro o amenazadas. | D14: Medio | G14: Fácil | I14: 0 | J14: Bajo | L14: Permanente | M14: Ciudadano, familia, amigos, comunidad
A15: Consumir más vegetales | B15: 13 | C15: Aumentar la ingesta de frutas y verduras | D15: Alto | G15: Alta | I15: 0 | J15: Bajo | L15: Continuo | M15: Ciudadano, Familia
A16: Elegir productos orgánicos | B16: 14 | C16: Preferir alimentos sin pesticidas o químicos | D16: Bajo | G16: Media | I16: 0 | J16: Medio | L16: Continuo | M16: Ciudadano, Familia
A17: Planificación y Preparación de Comidas
A18: Planificación de comidas | B18: 15 | C18: Organizar las comidas para reducir el desperdicio | D18: Medio | G18: Alta | I18: 0 | J18: Bajo | L18: Continuo | M18: Ciudadano, Familia
A19: Cocinar eficientemente | B19: 16 | C19: Utilizar métodos de cocción que ahorren energía | D19: Bajo | G19: Alta | I19: 0 | J19: Ninguno | L19: Continuo | M19: Ciudadano, Familia
A20: Cocinar más en casa | B20: 17 | C20: Cocinar más en casa en lugar de comer fuera o pedir comida a domicilio. | D20: Medio | G20: Fácil | I20: 0 | J20: Bajo | L20: Permanente | M20: Ciudadano, familia, amigos, comunidad
A21: Optimizar el almacenamiento de alimentos | B21: 18 | C21: Usar métodos y recipientes que prolonguen la frescura de los alimentos y evitar que se echen a perder. | D21: Bajo | G21: Fácil | I21: 0 | J21: Bajo | L21: Continuo | M21: Ciudadano
A22: Apoyo a la Agricultura y Producción Local
A23: Cultivar un huerto | B23: 19 | C23: Producir algunos alimentos en casa | D23: Bajo | G23: Media | I23: 0 | J23: Variable | L23: Largo plazo | M23: Ciudadano, Familia
A24: Comprar productos locales | B24: 20 | C24: Prefiere alimentos producidos localmente | D24: Medio | G24: Alta | I24: 0 | J24: Bajo | L24: Continuo | M24: Ciudadano, Comunidad
A25: Consumir productos de temporada (y locales si se puede a la vez) | B25: 21 | C25: Elegir alimentos que se producen en la zona y que se recogen en su momento óptimo de maduración. | D25: Alto | G25: Fácil | I25: 0 | J25: Bajo | L25: Permanente | M25: Ciudadano, familia, amigos, comunidad
A26: Apoyar a la agricultura local | B26: 22 | C26: Comprar productos de la agricultura local, que suelen tener una huella de carbono más baja que los productos importados. | D26: Medio | G26: Fácil | I26: 0 | J26: Bajo | L26: Permanente | M26: Ciudadano, familia, amigos, comunidad
A27: Sostenibilidad y Consumo Responsable
A28: Comprar productos de segunda mano para preparación de alimentos | B28: 23 | C28: Ejemplo: una fregadera, una vajilla, vasos, copas, cubertería. | D28: Bajo | G28: Fácil | I28: 0 | J28: Bajo | L28: Continuo | M28: Ciudadano
A29: Utilizar bolsas de compra reutilizables | B29: 24 | C29: Llevar bolsas de compra reutilizables al supermercado en lugar de usar bolsas de plástico desechables. | D29: Alto | G29: Fácil | I29: 0 | J29: Bajo | L29: Permanente | M29: Ciudadano, familia, amigos, comunidad
A30: Evitar los productos con un embalaje de plástico excesivo | B30: 25 | C30: Elegir productos con un embalaje de plástico reducido o, en su caso, optar por productos sin embalaje. | D30: Medio | G30: Fácil | I30: 0 | J30: Bajo | L30: Permanente | M30: Ciudadano, familia, amigos, comunidad
A31: Reducir el desperdicio alimentario | B31: 26 | C31: Planificar las comidas con antelación, cocinar la cantidad adecuada de comida y guardar las sobras adecuadamente. | D31: Alto | G31: Fácil | I31: 0 | J31: Bajo | L31: Permanente | M31: Ciudadano, familia, amigos, comunidad
A32: Añade tus propias ideas y llevalas a "Mis ideas"

Sheet 3.2. Calculo dieta y cons....
B1: Acciones del grupo Dieta y consumo de alimentos | C1: Como se calcula la reducción al realizar la acción | D1: Notas personales
B2: Políticas de Consumo
A3: 1 | B3: Busca cooperativas de consumo en tu barrio | C3: Se reduce la distancia de transporte. Por cada 50 Km reducidos: reducción de CO₂ = 50 km * 0.16 kg CO₂/km = 8 kg CO₂ evitados.
A4: 2 | B4: Usar apps para evitar el desperdicio de alimentos | C4: Por cada kg de comida desperdiciada se genera una huella promedio de 3.5 kg CO₂. Si salvas 10 kg al año. Reducción de CO₂ = 10 kg * 3.5 kg CO₂/kg = 35 kg CO₂ evitados.
A5: 3 | B5: Apoyar iniciativas locales de reducción de desperdicios | C5: Similar al anterior, dependerá del desperdicio evitado.
A6: 5 | B6: Educar y concienciar. | C6: Estima cuántas personas cambian su comportamiento y el alimento que ahorran o CO₂ que evitan.
A7: 6 | B7: Involucrarse en políticas alimentarias. | C7: Si una política reduce un 10% del consumo de carne en una comunidad de 1000 personas (suponiendo 100 kg carne/persona/año y 50 kg CO₂/kg carne): Reducción 1000 personas * 100 kg * 10% * 50 kg CO₂/kg = 500,000 kg CO₂ evitados
B8: Dieta y Alimentación
A9: 7 | B9: Limitar el consumo de carne, especialmente de carne de vacuno | C9: Reducción: Aproximadamente 27 kg de CO2e por cada kg de carne de vacuno no consumido.
A10: 8 | B10: Reducir el consumo de lácteos | C10: Reducción: Aproximadamente 3 kg de CO2e por cada litro de leche no consumido.
A11: 9 | B11: Reducir alimentos procesados | C11: Reducción: Varia mucho, un promedio puede ser 2-5 kg CO2e/kg. por kg de alimento procesado no consumido.
A12: 10 | B12: Evitar comidas rápidas | C12: Reducción: Variable, pero las comidas rápidas tienden a tener una huella de carbono alta debido a la producción industrial y transporte.
A13: 11 | B13: Consumir porciones adecuadas | C13: Reducción: Puede reducir el desperdicio de alimentos.
A14: 12 | B14: Consumir pescado obtenido mediante pesca sostenible | C14: Reducción:Pescado convencional: 2.5 kg CO2e/kg. Pescado sostenible 1.5 kg CO2e/kg. Por cada Kg de pescado obtenido mediante pesca sostenible, se reduce 1 kg CO2e/kg.
A15: 13 | B15: Consumir más vegetales | C15: Reducción: Aproximadamente 2-5 kg de CO2e por cada kg de carne sustituido por vegetales.
A16: 14 | B16: Elegir productos orgánicos | C16: Reducción: Variable.
B17: Planificación y Preparación de Comidas
A18: 15 | B18: Planificación de comidas | C18: Reducción: Puede reducir el desperdicio de alimentos.
A19: 16 | B19: Cocinar eficientemente | C19: Reducción: puede ahorrar aproximadamente 0.5 kg CO2e por día.
A20: 17 | B20: Cocinar más en casa | C20: Reducción: Variable.
A21: 18 | B21: Optimizar el almacenamiento de alimentos | C21: Reducción: Variable.
B22: Apoyo a la Agricultura y Producción Local
A23: 19 | B23: Cultivar un huerto | C23: Reducción variable: En función de la producción anual del huerto: los kilos que se producen.
A24: 20 | B24: Comprar productos locales | C24: Reducción: Variable, se reducen las emisiones del transporte de alimentos, aprox 0.1-0.3 kg de CO2e por cada kg de alimentos.
A25: 21 | B25: Consumir productos de temporada (y locales si se puede a la vez) | C25: Reducción: 50 kg de frutas y verduras de temporada en lugar de importadas, requieren 50% menos de energía de transporte y almacenamiento, podrías evitar 10-20 kg de CO₂ al año.
A26: 22 | B26: Apoyar a la agricultura local | C26: Reducción: Similar a comprar productos locales, con un enfoque en sostenibilidad.
B27: Sostenibilidad y Consumo Responsable
A28: 23 | B28: Comprar productos de segunda mano para preparación de alimentos | C28: Reducción: La huella evitada será cercana a la huella de carbono de su fabricación. (fabricar un pequeño electrodoméstico puede emitir de 20-100 kg de CO₂ dependiendo de su tamaño y materiales.)
A29: 24 | B29: Utilizar bolsas de compra reutilizables | C29: Reducción: Aproximadamente 0.1-0.2 kg de CO2e por cada bolsa de plástico evitada.
A30: 25 | B30: Evitar los productos con un embalaje de plástico excesivo | C30: Reducción: Variable, pero reducir el plástico disminuye las emisiones de producción y residuos.
A31: 26 | B31: Reducir el desperdicio alimentario | C31: Reducción: Variable.
B32: Añade tus propias ideas

Sheet 4.1. Compras y consumos
A1: Acciones del grupo compras y consumos | B1: Acción nº | C1: Descripción | D1: Impacto Potencial | E1: Puedo Aplicarla? | F1: Que % puedo aplicar | G1: Facilidad de Ejecución | H1: En que periodo de tiempo puedo implementarla ? | I1: Cuánto Carbono ( kg o % ) Creo que puedo evitar / ahorrar / quitar? | J1: Coste | K1: Cuánto me va a costar? ( Indique €uros Anuales ) | L1: Duración | M1: Rol (Ciudadano, Empleado, Familia, Amigos, Comunidad)
A2: Moda y Consumo Responsable:
A3: Comprar ropa sostenible | B3: 1 | C3: Elegir prendas de marcas sostenibles y de calidad | D3: Moderado | G3: Moderado | I3: 0 | J3: Variable | L3: Continuo | M3: Ciudadano
A4: Apoyar la moda sostenible | B4: 2 | C4: Comprar ropa de marcas que promuevan la sostenibilidad y la ética en la moda | D4: Moderado | G4: Moderado | I4: 0 | J4: Variable | L4: Continuo | M4: Ciudadano, Familia
A5: Comprar ropa de segunda mano | B5: 3 | C5: Adquirir ropa de segunda mano o intercambiarla en lugar de comprar nueva | D5: Moderado | G5: Fácil | I5: 0 | J5: Variable | L5: Continuo | M5: Ciudadano, Familia
A6: Reciclar ropa | B6: 4 | C6: Donar o reciclar ropa en lugar de desecharla | D6: Moderado | G6: Fácil | I6: 0 | J6: Ninguno | L6: Continuo | M6: Ciudadano, Familia
A7: Reciclaje y Residuos:
A8: Reciclar correctamente | B8: 5 | C8: Separar y reciclar materiales adecuadamente | D8: Moderado | G8: Fácil | I8: 0 | J8: Bajo | L8: Continuo | M8: Ciudadano, Familia
A9: Compostar los residuos orgánicos | B9: 6 | C9: Implementar un sistema de compostaje para reducir la cantidad de desechos orgánicos | D9: Moderado | G9: Moderado | I9: 0 | J9: Variable | L9: Continuo | M9: Ciudadano, Familia
A10: Reducir plásticos | B10: 7 | C10: Evitar productos de un solo uso y optar por alternativas reutilizables | D10: Moderado | G10: Fácil | I10: 0 | J10: Variable | L10: Continuo | M10: Ciudadano, Familia
A11: Alimentación:
A12: Adoptar una dieta vegetariana o vegana | B12: 8 | C12: Eliminar o reducir significativamente el consumo de productos de origen animal | D12: Alto | G12: Moderado | I12: 0 | J12: Variable | L12: Continuo | M12: Ciudadano, Familia
A13: Transporte
A14: Utilizar bicicleta o caminar | B14: 9 | C14: Optar por medios de transporte sostenibles como la bicicleta o caminar en distancias cortas | D14: Alto | G14: Fácil | I14: 0 | J14: Bajo | L14: Continuo | M14: Ciudadano, Familia
A15: Consumo Responsable y Minimalismo:
A16: Reducir el consumo innecesario | B16: 10 | C16: Evitar compras impulsivas y apostar por productos duraderos. | D16: Moderado | G16: Moderado | I16: 0 | J16: Variable | L16: Continuo | M16: Ciudadano
A17: Priorizar la segunda mano y la reutilización | B17: 11 | C17: Reutilizar o reparar productos antes de comprar nuevos. | D17: Moderado | G17: Moderado | I17: 0 | J17: Variable | L17: Continuo | M17: Ciudadano
A18: Evitar productos con embalajes innecesarios. | B18: 12 | C18: Preferir envases biodegradables o reutilizables. | D18: Moderado | G18: Moderado | I18: 0 | J18: Variable | L18: Continuo | M18: Ciudadano
A19: Considerar la huella de carbono de las compras online. | B19: 13 | C19: Planificar para minimizar envíos y evitar devoluciones innecesarias. | D19: Moderado | G19: Moderado | I19: 0 | J19: Ninguno | L19: Continuo | M19: Ciudadano
A20: Priorizar calidad sobre cantidad. | B20: 14 | C20: Invertir en productos duraderos. | D20: Moderado | G20: Fácil | I20: 0 | J20: Variable | L20: Continuo | M20: Ciudadano
A21: Evitar productos no esenciales. | B21: 15 | C21: Cuestionar si realmente se necesita un nuevo producto. | D21: Alto | G21: media | I21: 0 | J21: Ninguno | L21: Continuo | M21: Ciudadano
A22: Llevar tus propias bolsas y envases. | B22: 16 | C22: Evita usar bolsas plásticas desechables al hacer tus compras. | D22: Alto | G22: Fácil | I22: 0 | J22: bajo | L22: Continuo | M22: Ciudadano
A23: Priorizar la segunda mano y la reutilización:
A24: Comprar productos de segunda mano. | B24: 17 | C24: Ropa, muebles, libros y tecnología de segunda mano son opciones más sostenibles. | D24: Moderado | G24: Fácil | I24: 0 | J24: Variable | L24: Continuo | M24: Ciudadano
A25: Reciclar y reutilizar ropa y objetos. | B25: 18 | C25: Repara o transforma productos antes de desecharlos. | D25: Moderado | G25: Fácil | I25: 0 | J25: Ninguno | L25: Continuo | M25: Ciudadano
A26: Consumir Menos y Mejor:
A27: Reparar en lugar de reemplazar. | B27: 19 | C27: Arreglar productos antes de desecharlos. | D27: Moderado | G27: media | I27: 0 | J27: bajo | L27: Continuo | M27: Ciudadano
A28: Intercambiar productos. | B28: 20 | C28: Participar en intercambios o compartir recursos. | D28: Moderado | G28: Fácil | I28: 0 | J28: Ninguno | L28: Continuo | M28: Ciudadano
A29: Evitar Productos de Un Solo Uso:
A30: Sustituir desechables por reutilizables. | B30: 21 | C30: Usar botellas, bolsas, cubiertos y más reutilizables. | D30: Alto | G30: Fácil | I30: 0 | J30: Bajo | L30: Continuo | M30: Ciudadano
A31: Optar por cosméticos sólidos o sin envases. | B31: 22 | C31: Elegir productos que generen menos residuos. | D31: Moderado | G31: Fácil | I31: 0 | J31: Variable | L31: Continuo | M31: Ciudadano
A32: Favorecer productos con ciclo de vida sostenible:
A33: Considerar la durabilidad y reciclabilidad. | B33: 23 | C33: Elige productos diseñados para durar y ser reciclados o compostados al final de su vida útil. | D33: Alto | G33: Moderado | I33: 0 | J33: Variable | L33: Continuo | M33: Ciudadano
A34: Preferir productos con economía circular. | B34: 24 | C34: Busca productos hechos con materiales reciclados o que puedan ser devueltos para ser transformados en nuevos productos | D34: Alto | G34: Moderado | I34: 0 | J34: Variable | L34: Continuo | M34: Ciudadano
A35: Planificar las compras:
A36: Hacer listas de compras. | B36: 25 | C36: Planea lo que necesitas para evitar compras impulsivas | D36: Moderado | G36: Fácil | I36: 0 | J36: Ninguno | L36: Continuo | M36: Ciudadano
A37: Evitar las modas pasajeras. | B37: 26 | C37: No te dejes llevar por tendencias efímeras y apuesta por productos atemporales | D37: Moderado | G37: Moderado | I37: 0 | J37: Ninguno | L37: Continuo | M37: Ciudadano
A38: Involucrarse en la comunidad:
A39: Compartir recursos y herramientas. | B39: 27 | C39: Participa en grupos locales que promuevan el compartir y alquilar herramientas, libros y otros bienes | D39: Moderado | G39: Moderado | I39: 0 | J39: Ninguno | L39: Continuo | M39: Ciudadano
A40: Unirse a bancos de tiempo o cooperativas de consumo. | B40: 28 | C40: Estas iniciativas permiten intercambiar servicios y productos sin necesidad de comprar | D40: Moderado | G40: Moderado | I40: 0 | J40: Ninguno | L40: Continuo | M40: Ciudadano
...

Sheet 4.2. Calculo compras y consumos
A1: Acciones del grupo compras y consumos | B1: Como se calcula la reducción al realizar la acción | C1: Notas personales
A2: Moda y Consumo Responsable:
A3: Comprar ropa sostenible | B3: Ahorra hasta un 30% de emisiones en comparación con la ropa convencional.
A4: Apoyar la moda sostenible | B4: Similar al anterior.
A5: Comprar ropa de segunda mano | B5: Ahorra hasta el 70% de la huella de carbono por evitar la fabricación de productos nuevos.
A6: Reciclar ropa | B6: Evitar el 50-70% de las emisiones por producción de nuevos productos.
A7: Reciclaje y Residuos:
A8: Reciclar correctamente | B8: Reduce hasta el 80% de las emisiones asociadas a los desechos no reciclados.
A9: Compostar los residuos orgánicos | B9: Evita 200-300 kg CO₂ al año.
A10: Reducir plásticos | B10: Depende del uso de plásticos.
A11: Alimentación:
A12: Adoptar una dieta vegetariana o vegana | B12: Reducción de hasta el 50% en la huella alimentaria.
A13: Transporte
A14: Utilizar bicicleta o caminar | B14: Evita 1 kg de CO₂ por cada 5 km que evitas usar el coche.
A15: Consumo Responsable y Minimalismo:
A16: Reducir el consumo innecesario | B16: Disminuye tu huella de carbono en un 10-20%.
A17: Priorizar la segunda mano y la reutilización | B17: Ahorra hasta el 70% de la huella de carbono por evitar la fabricación de productos nuevos.
A18: Evitar productos con embalajes innecesarios. | B18: Por cada kg de plástico que se evita, se puede reducir de 1.8 a 3.2 kg de CO₂. Varía según el tipo de plástico y el proceso de producción o reciclaje implicado.
A19: Considerar la huella de carbono de las compras online. | B19: Evitar devoluciones y minimizar envíos puede reducir un 10-20% la huella de carbono por compra
A20: Priorizar calidad sobre cantidad. | B20: Menos productos implica una reducción de hasta un 30% en la huella carbono personal.
A21: Evitar productos no esenciales. | B21: Reducción de hasta el 50% de las emisiones relacionadas.
A22: Llevar tus propias bolsas y envases. | B22: Por cada kg de plástico que se evita, se puede reducir de 1.8 a 3.2 kg de CO₂. Varía según el tipo de plástico y el proceso de producción o reciclaje implicado.
A23: Priorizar la segunda mano y la reutilización:
A24: Comprar productos de segunda mano. | B24: Ahorra hasta el 70% de la huella de carbono por evitar la fabricación de productos nuevos.
A25: Reciclar y reutilizar ropa y objetos. | B25: Evitar el 50-70% de las emisiones por producción de nuevos productos.
A26: Consumir Menos y Mejor:
A27: Reparar en lugar de reemplazar. | B27: Ahorra hasta un 50% en comparación con comprar un producto nuevo.
A28: Intercambiar productos. | B28: Evitar el 50-70% de las emisiones por producción de nuevos productos.
A29: Evitar Productos de Un Solo Uso:
A30: Sustituir desechables por reutilizables. | B30: Depende del uso de plásticos de un solo uso.
A31: Optar por cosméticos sólidos o sin envases. | B31: Por cada kg de plástico que se evita, se puede reducir de 1.8 a 3.2 kg de CO₂. Varía según el tipo de plástico y el proceso de producción o reciclaje implicado.
A32: Favorecer productos con ciclo de vida sostenible:
A33: Considerar la durabilidad y reciclabilidad. | B33: Reduce la necesidad de fabricar nuevos productos, y puede ahorrar un 30-50% de emisiones.
A34: Preferir productos con economía circular. | B34: puede reducir hasta un 50% de la huella de carbono.
A35: Planificar las compras:
A36: Hacer listas de compras. | B36: Se pueden reducir emisiones por fabricación y transporte.
A37: Evitar las modas pasajeras. | B37: Evita compras innecesarias y puede ahorrar un 10-20% en la huella de carbono asociada al consumo
A38: Involucrarse en la comunidad:
A39: Compartir recursos y herramientas. | B39: Puede reducir hasta un 50% de la huella de carbono de estos productos.
A40: Unirse a bancos de tiempo o cooperativas de consumo. | B40: Puede reducir hasta un 50% de la huella de carbono de los bienes intercambiados
...

Sheet 5.1. Gestión de Residuos 
A1: Acciones del grupo Gestión de Residuos | B1: Nº | C1: Descripción | D1: Impacto Potencial | E1: Puedo Aplicarla? | F1: Que % puedo aplicar | G1: Facilidad de Ejecución | H1: En que periodo de tiempo puedo implementarla ? | I1: Cuánto Carbono ( kg o % ) Creo que puedo evitar / ahorrar / quitar? | J1: Coste | K1: Cuánto me va a costar? ( Indique €uros Anuales ) | L1: Duración | M1: Rol (Ciudadano, Empleado, Familia, Amigos, Comunidad)
A2: Reducción de Productos Desechables y Limpieza
A3: Reducir el uso de productos desechables | B3: 1 | C3: Evitar el uso de utensilios, platos y vasos desechables | D3: Moderado | G3: Fácil | I3: 0 | J3: Bajo | L3: Continuo | M3: Ciudadano, Familia
A4: Reducir el uso de productos de limpieza tóxicos | B4: 2 | C4: Optar por productos de limpieza ecológicos y reutilizables | D4: Moderado | G4: Fácil | I4: 0 | J4: Variable | L4: Continuo | M4: Ciudadano, Familia
A5: Reducir el uso de productos de limpieza desechables | B5: 3 | C5: Optar por trapos y esponjas reutilizables en lugar de productos desechables | D5: Moderado | G5: Fácil | I5: 0 | J5: Bajo | L5: Continuo | M5: Ciudadano, Familia
A6: Evitar el consumo de agua embotellada | B6: 4 | C6: Beber agua del grifo o utilizar una botella reutilizable | D6: Moderado | G6: Fácil | I6: 0 | J6: Bajo | L6: Continuo | M6: Ciudadano, Familia
A7: Evitar el uso de pajitas de plástico | B7: 5 | C7: Optar por pajitas reutilizables o no usar pajitas en absoluto | D7: Bajo | G7: Fácil | I7: 0 | J7: Bajo | L7: Continuo | M7: Ciudadano, Familia
A8: Utilizar papel reciclado | B8: 7 | C8: Comprar papel y productos hechos con papel reciclado | D8: Moderado | G8: Fácil | I8: 0 | J8: Variable | L8: Continuo | M8: Ciudadano, Empleado
A9: Utilizar pañuelos de tela | B9: 8 | C9: Sustituir pañuelos de papel por pañuelos de tela | D9: Moderado | G9: Fácil | I9: 0 | J9: Bajo | L9: Continuo | M9: Ciudadano, Familia
